Workbook

Sheet Read Me
A1: PCSO Lotto Draw Results — 10 Mar to 10 Jun 2026 (3 months)
A3: Games: Lotto 6/42, Mega 6/45, Super 6/49, Grand 6/55, Ultra 6/58 — 194 draws total.
A4: Primary source: PCSO official search page (pcso.gov.ph/SearchLottoResult.aspx).
A5: History compiled from lottopcso.com archives; every draw overlapping the official PCSO table (Jun 7-10) was verified to match exactly.
A6: Known gaps in the archive: 6/58 on Apr 3; 6/42 on Apr 2 and Apr 4 (no results published).
A8: HOW MUCH DATA GIVES 'HIGH STATISTICAL PROBABILITY'? — The honest answer
A10: Each draw is an independent random event. Past draws carry zero information about future draws,
A11: so NO amount of historical data — 3 months or 30 years — improves your odds of predicting the next result.
A12: The probability of any specific 6-number ticket stays fixed: 1 in 5,245,786 (6/42) up to 1 in 40,475,358 (6/58).
A14: What sample sizes ARE good for:
A15: ~50 draws per game (this file has ~39): enough to run a chi-square uniformity check (see Frequency sheet).
A16: ~400-1,000 draws (2-6 years): enough to confirm the machine has no large bias (>20% on a single number).
... A23: Please play responsibly — PCSO's own responsible-gaming page: pcso.gov.ph/Games/ResponsibleGaming.aspx

Sheet Draws
A1: Game | B1: Draw Date | C1: N1 | D1: N2 | E1: N3 | F1: N4 | G1: N5 | H1: N6
A2: Lotto 6/42 | B2: 2026-03-10 | C2: 3 | D2: 29 | E2: 12 | F2: 33 | G2: 10 | H2: 16
A3: Lotto 6/42 | B3: 2026-03-12 | C3: 35 | D3: 2 | E3: 40 | F3: 36 | G3: 13 | H3: 16
A4: Lotto 6/42 | B4: 2026-03-14 | C4: 26 | D4: 13 | E4: 35 | F4: 11 | G4: 18 | H4: 32
A5: Lotto 6/42 | B5: 2026-03-17 | C5: 17 | D5: 36 | E5: 5 | F5: 7 | G5: 8 | H5: 38
A6: Lotto 6/42 | B6: 2026-03-19 | C6: 25 | D6: 29 | E6: 17 | F6: 41 | G6: 23 | H6: 13
A7: Lotto 6/42 | B7: 2026-03-21 | C7: 18 | D7: 12 | E7: 37 | F7: 2 | G7: 30 | H7: 24
A8: Lotto 6/42 | B8: 2026-03-24 | C8: 13 | D8: 41 | E8: 27 | F8: 29 | G8: 42 | H8: 8
A9: Lotto 6/42 | B9: 2026-03-26 | C9: 29 | D9: 15 | E9: 3 | F9: 18 | G9: 23 | H9: 30
A10: Lotto 6/42 | B10: 2026-03-28 | C10: 11 | D10: 23 | E10: 9 | F10: 5 | G10: 1 | H10: 3
A11: Lotto 6/42 | B11: 2026-03-31 | C11: 16 | D11: 22 | E11: 3 | F11: 30 | G11: 36 | H11: 4
A12: Lotto 6/42 | B12: 2026-04-07 | C12: 6 | D12: 37 | E12: 23 | F12: 2 | G12: 39 | H12: 31
A13: Lotto 6/42 | B13: 2026-04-09 | C13: 41 | D13: 38 | E13: 3 | F13: 5 | G13: 11 | H13: 6
... A225: Grand Lotto 6/55 | B225: 2026-06-24 | C225: 22 | D225: 51 | E225: 17 | F225: 23 | G225: 54 | H225: 29

Sheet Frequency
A1: Number | B1: Lotto 6/42 | C1: Mega Lotto 6/45 | D1: Super Lotto 6/49 | E1: Grand Lotto 6/55 | F1: Ultra Lotto 6/58
A2: 1 | B2: =SUMPRODUCT((Draws!$A$2:$A$225=B$1)*(Draws!$C$2:$H$225=$A2)) -> 5 | C2: =SUMPRODUCT((Draws!$A$2:$A$225=C$1)*(Draws!$C$2:$H$225=$A2)) -> 4 | D2: =SUMPRODUCT((Draws!$A$2:$A$225=D$1)*(Draws!$C$2:$H$225=$A2)) -> 4 | E2: =SUMPRODUCT((Draws!$A$2:$A$225=E$1)*(Draws!$C$2:$H$225=$A2)) -> 3 | F2: =SUMPRODUCT((Draws!$A$2:$A$225=F$1)*(Draws!$C$2:$H$225=$A2)) -> 4
A3: 2 | B3: =SUMPRODUCT((Draws!$A$2:$A$225=B$1)*(Draws!$C$2:$H$225=$A3)) -> 6 | C3: =SUMPRODUCT((Draws!$A$2:$A$225=C$1)*(Draws!$C$2:$H$225=$A3)) -> 3 | D3: =SUMPRODUCT((Draws!$A$2:$A$225=D$1)*(Draws!$C$2:$H$225=$A3)) -> 6 | E3: =SUMPRODUCT((Draws!$A$2:$A$225=E$1)*(Draws!$C$2:$H$225=$A3)) -> 6 | F3: =SUMPRODUCT((Draws!$A$2:$A$225=F$1)*(Draws!$C$2:$H$225=$A3)) -> 5
A4: 3 | B4: =SUMPRODUCT((Draws!$A$2:$A$225=B$1)*(Draws!$C$2:$H$225=$A4)) -> 12 | C4: =SUMPRODUCT((Draws!$A$2:$A$225=C$1)*(Draws!$C$2:$H$225=$A4)) -> 6 | D4: =SUMPRODUCT((Draws!$A$2:$A$225=D$1)*(Draws!$C$2:$H$225=$A4)) -> 6 | E4: =SUMPRODUCT((Draws!$A$2:$A$225=E$1)*(Draws!$C$2:$H$225=$A4)) -> 3 | F4: =SUMPRODUCT((Draws!$A$2:$A$225=F$1)*(Draws!$C$2:$H$225=$A4)) -> 3
A5: 4 | B5: =SUMPRODUCT((Draws!$A$2:$A$225=B$1)*(Draws!$C$2:$H$225=$A5)) -> 4 | C5: =SUMPRODUCT((Draws!$A$2:$A$225=C$1)*(Draws!$C$2:$H$225=$A5)) -> 10 | D5: =SUMPRODUCT((Draws!$A$2:$A$225=D$1)*(Draws!$C$2:$H$225=$A5)) -> 9 | E5: =SUMPRODUCT((Draws!$A$2:$A$225=E$1)*(Draws!$C$2:$H$225=$A5)) -> 4 | F5: =SUMPRODUCT((Draws!$A$2:$A$225=F$1)*(Draws!$C$2:$H$225=$A5)) -> 3
A6: 5 | B6: =SUMPRODUCT((Draws!$A$2:$A$225=B$1)*(Draws!$C$2:$H$225=$A6)) -> 7 | C6: =SUMPRODUCT((Draws!$A$2:$A$225=C$1)*(Draws!$C$2:$H$225=$A6)) -> 8 | D6: =SUMPRODUCT((Draws!$A$2:$A$225=D$1)*(Draws!$C$2:$H$225=$A6)) -> 3 | E6: =SUMPRODUCT((Draws!$A$2:$A$225=E$1)*(Draws!$C$2:$H$225=$A6)) -> 6 | F6: =SUMPRODUCT((Draws!$A$2:$A$225=F$1)*(Draws!$C$2:$H$225=$A6)) -> 5
A7: 6 | B7: =SUMPRODUCT((Draws!$A$2:$A$225=B$1)*(Draws!$C$2:$H$225=$A7)) -> 6 | C7: =SUMPRODUCT((Draws!$A$2:$A$225=C$1)*(Draws!$C$2:$H$225=$A7)) -> 3 | D7: =SUMPRODUCT((Draws!$A$2:$A$225=D$1)*(Draws!$C$2:$H$225=$A7)) -> 6 | E7: =SUMPRODUCT((Draws!$A$2:$A$225=E$1)*(Draws!$C$2:$H$225=$A7)) -> 2 | F7: =SUMPRODUCT((Draws!$A$2:$A$225=F$1)*(Draws!$C$2:$H$225=$A7)) -> 3
A8: 7 | B8: =SUMPRODUCT((Draws!$A$2:$A$225=B$1)*(Draws!$C$2:$H$225=$A8)) -> 9 | C8: =SUMPRODUCT((Draws!$A$2:$A$225=C$1)*(Draws!$C$2:$H$225=$A8)) -> 3 | D8: =SUMPRODUCT((Draws!$A$2:$A$225=D$1)*(Draws!$C$2:$H$225=$A8)) -> 3 | E8: =SUMPRODUCT((Draws!$A$2:$A$225=E$1)*(Draws!$C$2:$H$225=$A8)) -> 2 | F8: =SUMPRODUCT((Draws!$A$2:$A$225=F$1)*(Draws!$C$2:$H$225=$A8)) -> 3
A9: 8 | B9: =SUMPRODUCT((Draws!$A$2:$A$225=B$1)*(Draws!$C$2:$H$225=$A9)) -> 5 | C9: =SUMPRODUCT((Draws!$A$2:$A$225=C$1)*(Draws!$C$2:$H$225=$A9)) -> 8 | D9: =SUMPRODUCT((Draws!$A$2:$A$225=D$1)*(Draws!$C$2:$H$225=$A9)) -> 7 | E9: =SUMPRODUCT((Draws!$A$2:$A$225=E$1)*(Draws!$C$2:$H$225=$A9)) -> 4 | F9: =SUMPRODUCT((Draws!$A$2:$A$225=F$1)*(Draws!$C$2:$H$225=$A9)) -> 7
A10: 9 | B10: =SUMPRODUCT((Draws!$A$2:$A$225=B$1)*(Draws!$C$2:$H$225=$A10)) -> 5 | C10: =SUMPRODUCT((Draws!$A$2:$A$225=C$1)*(Draws!$C$2:$H$225=$A10)) -> 6 | D10: =SUMPRODUCT((Draws!$A$2:$A$225=D$1)*(Draws!$C$2:$H$225=$A10)) -> 8 | E10: =SUMPRODUCT((Draws!$A$2:$A$225=E$1)*(Draws!$C$2:$H$225=$A10)) -> 7 | F10: =SUMPRODUCT((Draws!$A$2:$A$225=F$1)*(Draws!$C$2:$H$225=$A10)) -> 8
A11: 10 | B11: =SUMPRODUCT((Draws!$A$2:$A$225=B$1)*(Draws!$C$2:$H$225=$A11)) -> 6 | C11: =SUMPRODUCT((Draws!$A$2:$A$225=C$1)*(Draws!$C$2:$H$225=$A11)) -> 9 | D11: =SUMPRODUCT((Draws!$A$2:$A$225=D$1)*(Draws!$C$2:$H$225=$A11)) -> 5 | E11: =SUMPRODUCT((Draws!$A$2:$A$225=E$1)*(Draws!$C$2:$H$225=$A11)) -> 6 | F11: =SUMPRODUCT((Draws!$A$2:$A$225=F$1)*(Draws!$C$2:$H$225=$A11)) -> 2
A12: 11 | B12: =SUMPRODUCT((Draws!$A$2:$A$225=B$1)*(Draws!$C$2:$H$225=$A12)) -> 6 | C12: =SUMPRODUCT((Draws!$A$2:$A$225=C$1)*(Draws!$C$2:$H$225=$A12)) -> 7 | D12: =SUMPRODUCT((Draws!$A$2:$A$225=D$1)*(Draws!$C$2:$H$225=$A12)) -> 7 | E12: =SUMPRODUCT((Draws!$A$2:$A$225=E$1)*(Draws!$C$2:$H$225=$A12)) -> 2 | F12: =SUMPRODUCT((Draws!$A$2:$A$225=F$1)*(Draws!$C$2:$H$225=$A12)) -> 4
A13: 12 | B13: =SUMPRODUCT((Draws!$A$2:$A$225=B$1)*(Draws!$C$2:$H$225=$A13)) -> 10 | C13: =SUMPRODUCT((Draws!$A$2:$A$225=C$1)*(Draws!$C$2:$H$225=$A13)) -> 6 | D13: =SUMPRODUCT((Draws!$A$2:$A$225=D$1)*(Draws!$C$2:$H$225=$A13)) -> 3 | E13: =SUMPRODUCT((Draws!$A$2:$A$225=E$1)*(Draws!$C$2:$H$225=$A13)) -> 3 | F13: =SUMPRODUCT((Draws!$A$2:$A$225=F$1)*(Draws!$C$2:$H$225=$A13)) -> 6
... A43: 42 | B43: =SUMPRODUCT((Draws!$A$2:$A$225=B$1)*(Draws!$C$2:$H$225=$A43)) -> 7 | C43: =SUMPRODUCT((Draws!$A$2:$A$225=C$1)*(Draws!$C$2:$H$225=$A43)) -> 5 | D43: =SUMPRODUCT((Draws!$A$2:$A$225=D$1)*(Draws!$C$2:$H$225=$A43)) -> 8 | E43: =SUMPRODUCT((Draws!$A$2:$A$225=E$1)*(Draws!$C$2:$H$225=$A43)) -> 11 | F43: =SUMPRODUCT((Draws!$A$2:$A$225=F$1)*(Draws!$C$2:$H$225=$A43)) -> 6
A44: 43 | C44: =SUMPRODUCT((Draws!$A$2:$A$225=C$1)*(Draws!$C$2:$H$225=$A44)) -> 9 | D44: =SUMPRODUCT((Draws!$A$2:$A$225=D$1)*(Draws!$C$2:$H$225=$A44)) -> 8 | E44: =SUMPRODUCT((Draws!$A$2:$A$225=E$1)*(Draws!$C$2:$H$225=$A44)) -> 11 | F44: =SUMPRODUCT((Draws!$A$2:$A$225=F$1)*(Draws!$C$2:$H$225=$A44)) -> 7
A45: 44 | C45: =SUMPRODUCT((Draws!$A$2:$A$225=C$1)*(Draws!$C$2:$H$225=$A45)) -> 8 | D45: =SUMPRODUCT((Draws!$A$2:$A$225=D$1)*(Draws!$C$2:$H$225=$A45)) -> 12 | E45: =SUMPRODUCT((Draws!$A$2:$A$225=E$1)*(Draws!$C$2:$H$225=$A45)) -> 5 | F45: =SUMPRODUCT((Draws!$A$2:$A$225=F$1)*(Draws!$C$2:$H$225=$A45)) -> 1
A46: 45 | C46: =SUMPRODUCT((Draws!$A$2:$A$225=C$1)*(Draws!$C$2:$H$225=$A46)) -> 7 | D46: =SUMPRODUCT((Draws!$A$2:$A$225=D$1)*(Draws!$C$2:$H$225=$A46)) -> 4 | E46: =SUMPRODUCT((Draws!$A$2:$A$225=E$1)*(Draws!$C$2:$H$225=$A46)) -> 4 | F46: =SUMPRODUCT((Draws!$A$2:$A$225=F$1)*(Draws!$C$2:$H$225=$A46)) -> 11
A47: 46 | D47: =SUMPRODUCT((Draws!$A$2:$A$225=D$1)*(Draws!$C$2:$H$225=$A47)) -> 5 | E47: =SUMPRODUCT((Draws!$A$2:$A$225=E$1)*(Draws!$C$2:$H$225=$A47)) -> 8 | F47: =SUMPRODUCT((Draws!$A$2:$A$225=F$1)*(Draws!$C$2:$H$225=$A47)) -> 1
A48: 47 | D48: =SUMPRODUCT((Draws!$A$2:$A$225=D$1)*(Draws!$C$2:$H$225=$A48)) -> 6 | E48: =SUMPRODUCT((Draws!$A$2:$A$225=E$1)*(Draws!$C$2:$H$225=$A48)) -> 4 | F48: =SUMPRODUCT((Draws!$A$2:$A$225=F$1)*(Draws!$C$2:$H$225=$A48)) -> 6
A49: 48 | D49: =SUMPRODUCT((Draws!$A$2:$A$225=D$1)*(Draws!$C$2:$H$225=$A49)) -> 4 | E49: =SUMPRODUCT((Draws!$A$2:$A$225=E$1)*(Draws!$C$2:$H$225=$A49)) -> 7 | F49: =SUMPRODUCT((Draws!$A$2:$A$225=F$1)*(Draws!$C$2:$H$225=$A49)) -> 4
A50: 49 | D50: =SUMPRODUCT((Draws!$A$2:$A$225=D$1)*(Draws!$C$2:$H$225=$A50)) -> 4 | E50: =SUMPRODUCT((Draws!$A$2:$A$225=E$1)*(Draws!$C$2:$H$225=$A50)) -> 1 | F50: =SUMPRODUCT((Draws!$A$2:$A$225=F$1)*(Draws!$C$2:$H$225=$A50)) -> 2
A51: 50 | E51: =SUMPRODUCT((Draws!$A$2:$A$225=E$1)*(Draws!$C$2:$H$225=$A51)) -> 7 | F51: =SUMPRODUCT((Draws!$A$2:$A$225=F$1)*(Draws!$C$2:$H$225=$A51)) -> 7
A52: 51 | E52: =SUMPRODUCT((Draws!$A$2:$A$225=E$1)*(Draws!$C$2:$H$225=$A52)) -> 6 | F52: =SUMPRODUCT((Draws!$A$2:$A$225=F$1)*(Draws!$C$2:$H$225=$A52)) -> 7
A53: 52 | E53: =SUMPRODUCT((Draws!$A$2:$A$225=E$1)*(Draws!$C$2:$H$225=$A53)) -> 4 | F53: =SUMPRODUCT((Draws!$A$2:$A$225=F$1)*(Draws!$C$2:$H$225=$A53)) -> 6
A54: 53 | E54: =SUMPRODUCT((Draws!$A$2:$A$225=E$1)*(Draws!$C$2:$H$225=$A54)) -> 5 | F54: =SUMPRODUCT((Draws!$A$2:$A$225=F$1)*(Draws!$C$2:$H$225=$A54)) -> 7
A55: 54 | E55: =SUMPRODUCT((Draws!$A$2:$A$225=E$1)*(Draws!$C$2:$H$225=$A55)) -> 7 | F55: =SUMPRODUCT((Draws!$A$2:$A$225=F$1)*(Draws!$C$2:$H$225=$A55)) -> 3
A56: 55 | E56: =SUMPRODUCT((Draws!$A$2:$A$225=E$1)*(Draws!$C$2:$H$225=$A56)) -> 6 | F56: =SUMPRODUCT((Draws!$A$2:$A$225=F$1)*(Draws!$C$2:$H$225=$A56)) -> 4
A57: 56 | F57: =SUMPRODUCT((Draws!$A$2:$A$225=F$1)*(Draws!$C$2:$H$225=$A57)) -> 3
A58: 57 | F58: =SUMPRODUCT((Draws!$A$2:$A$225=F$1)*(Draws!$C$2:$H$225=$A58)) -> 5
A59: 58 | F59: =SUMPRODUCT((Draws!$A$2:$A$225=F$1)*(Draws!$C$2:$H$225=$A59)) -> 8
A61: Draws in sample | B61: =COUNTIF(Draws!$A:$A,B$1) -> 44 | C61: =COUNTIF(Draws!$A:$A,C$1) -> 45 | D61: =COUNTIF(Draws!$A:$A,D$1) -> 45 | E61: =COUNTIF(Draws!$A:$A,E$1) -> 45 | F61: =COUNTIF(Draws!$A:$A,F$1) -> 45
A62: Numbers in game | B62: 42 | C62: 45 | D62: 49 | E62: 55 | F62: 58
A63: Expected hits per number | B63: =B61*6/B62 -> 6.2857143 | C63: =C61*6/C62 -> 6 | D63: =D61*6/D62 -> 5.5102041 | E63: =E61*6/E62 -> 4.9090909 | F63: =F61*6/F62 -> 4.6551724
A64: Chi-square statistic | B64: =SUMPRODUCT((B2:B43-B63)^2)/B63 -> 30.636364 | C64: =SUMPRODUCT((C2:C46-C63)^2)/C63 -> 48.333333 | D64: =SUMPRODUCT((D2:D50-D63)^2)/D63 -> 42.511111 | E64: =SUMPRODUCT((E2:E56-E63)^2)/E63 -> 57.962963 | F64: =SUMPRODUCT((F2:F59-F63)^2)/F63 -> 62.103704
A65: Degrees of freedom | B65: 41 | C65: 44 | D65: 48 | E65: 54 | F65: 57
A66: p-value (uniformity test) | B66: =CHIDIST(B64,B65) -> 0.88156353 | C66: =CHIDIST(C64,C65) -> 0.30217135 | D66: =CHIDIST(D64,D65) -> 0.69648997 | E66: =CHIDIST(E64,E65) -> 0.33134149 | F66: =CHIDIST(F64,F65) -> 0.2992774
A67: Verdict at 5% level | B67: =IF(B66<0.05,"Deviates from uniform","Consistent with random") -> Consistent with random | C67: =IF(C66<0.05,"Deviates from uniform","Consistent with random") -> Consistent with random | D67: =IF(D66<0.05,"Deviates from uniform","Consistent with random") -> Consistent with random | E67: =IF(E66<0.05,"Deviates from uniform","Consistent with random") -> Consistent with random | F67: =IF(F66<0.05,"Deviates from uniform","Consistent with random") -> Consistent with random
A68: Hits = times a number was drawn, Mar 10 - Jun 16 2026. Expected = draws*6/pool. p>0.05 means frequencies look random.

Sheet Hot-Cold
A1: Hot (most drawn) and cold (least drawn) numbers per game — descriptive only, NOT predictive (see Read Me)
A3: Lotto 6/42 | D3: Mega Lotto 6/45 | G3: Super Lotto 6/49 | J3: Grand Lotto 6/55 | M3: Ultra Lotto 6/58
A4: Hot # | B4: Hits | D4: Hot # | E4: Hits | G4: Hot # | H4: Hits | J4: Hot # | K4: Hits | M4: Hot # | N4: Hits
A5: =INDEX(Frequency!$A$2:$A$43,MATCH(LARGE(Frequency!B2:B43,1),Frequency!B2:B43,0)) -> 3 | B5: =LARGE(Frequency!B2:B43,1) -> 12 | D5: =INDEX(Frequency!$A$2:$A$46,MATCH(LARGE(Frequency!C2:C46,1),Frequency!C2:C46,0)) -> 27 | E5: =LARGE(Frequency!C2:C46,1) -> 13 | G5: =INDEX(Frequency!$A$2:$A$50,MATCH(LARGE(Frequency!D2:D50,1),Frequency!D2:D50,0)) -> 44 | H5: =LARGE(Frequency!D2:D50,1) -> 12 | J5: =INDEX(Frequency!$A$2:$A$56,MATCH(LARGE(Frequency!E2:E56,1),Frequency!E2:E56,0)) -> 42 | K5: =LARGE(Frequency!E2:E56,1) -> 11 | M5: =INDEX(Frequency!$A$2:$A$59,MATCH(LARGE(Frequency!F2:F59,1),Frequency!F2:F59,0)) -> 20 | N5: =LARGE(Frequency!F2:F59,1) -> 11
A6: =INDEX(Frequency!$A$2:$A$43,MATCH(LARGE(Frequency!B2:B43,2),Frequency!B2:B43,0)) -> 12 | B6: =LARGE(Frequency!B2:B43,2) -> 10 | D6: =INDEX(Frequency!$A$2:$A$46,MATCH(LARGE(Frequency!C2:C46,2),Frequency!C2:C46,0)) -> 4 | E6: =LARGE(Frequency!C2:C46,2) -> 10 | G6: =INDEX(Frequency!$A$2:$A$50,MATCH(LARGE(Frequency!D2:D50,2),Frequency!D2:D50,0)) -> 4 | H6: =LARGE(Frequency!D2:D50,2) -> 9 | J6: =INDEX(Frequency!$A$2:$A$56,MATCH(LARGE(Frequency!E2:E56,2),Frequency!E2:E56,0)) -> 42 | K6: =LARGE(Frequency!E2:E56,2) -> 11 | M6: =INDEX(Frequency!$A$2:$A$59,MATCH(LARGE(Frequency!F2:F59,2),Frequency!F2:F59,0)) -> 20 | N6: =LARGE(Frequency!F2:F59,2) -> 11
A7: =INDEX(Frequency!$A$2:$A$43,MATCH(LARGE(Frequency!B2:B43,3),Frequency!B2:B43,0)) -> 12 | B7: =LARGE(Frequency!B2:B43,3) -> 10 | D7: =INDEX(Frequency!$A$2:$A$46,MATCH(LARGE(Frequency!C2:C46,3),Frequency!C2:C46,0)) -> 4 | E7: =LARGE(Frequency!C2:C46,3) -> 10 | G7: =INDEX(Frequency!$A$2:$A$50,MATCH(LARGE(Frequency!D2:D50,3),Frequency!D2:D50,0)) -> 4 | H7: =LARGE(Frequency!D2:D50,3) -> 9 | J7: =INDEX(Frequency!$A$2:$A$56,MATCH(LARGE(Frequency!E2:E56,3),Frequency!E2:E56,0)) -> 19 | K7: =LARGE(Frequency!E2:E56,3) -> 10 | M7: =INDEX(Frequency!$A$2:$A$59,MATCH(LARGE(Frequency!F2:F59,3),Frequency!F2:F59,0)) -> 9 | N7: =LARGE(Frequency!F2:F59,3) -> 8
A8: =INDEX(Frequency!$A$2:$A$43,MATCH(LARGE(Frequency!B2:B43,4),Frequency!B2:B43,0)) -> 7 | B8: =LARGE(Frequency!B2:B43,4) -> 9 | D8: =INDEX(Frequency!$A$2:$A$46,MATCH(LARGE(Frequency!C2:C46,4),Frequency!C2:C46,0)) -> 10 | E8: =LARGE(Frequency!C2:C46,4) -> 9 | G8: =INDEX(Frequency!$A$2:$A$50,MATCH(LARGE(Frequency!D2:D50,4),Frequency!D2:D50,0)) -> 4 | H8: =LARGE(Frequency!D2:D50,4) -> 9 | J8: =INDEX(Frequency!$A$2:$A$56,MATCH(LARGE(Frequency!E2:E56,4),Frequency!E2:E56,0)) -> 24 | K8: =LARGE(Frequency!E2:E56,4) -> 9 | M8: =INDEX(Frequency!$A$2:$A$59,MATCH(LARGE(Frequency!F2:F59,4),Frequency!F2:F59,0)) -> 9 | N8: =LARGE(Frequency!F2:F59,4) -> 8
A9: =INDEX(Frequency!$A$2:$A$43,MATCH(LARGE(Frequency!B2:B43,5),Frequency!B2:B43,0)) -> 7 | B9: =LARGE(Frequency!B2:B43,5) -> 9 | D9: =INDEX(Frequency!$A$2:$A$46,MATCH(LARGE(Frequency!C2:C46,5),Frequency!C2:C46,0)) -> 10 | E9: =LARGE(Frequency!C2:C46,5) -> 9 | G9: =INDEX(Frequency!$A$2:$A$50,MATCH(LARGE(Frequency!D2:D50,5),Frequency!D2:D50,0)) -> 4 | H9: =LARGE(Frequency!D2:D50,5) -> 9 | J9: =INDEX(Frequency!$A$2:$A$56,MATCH(LARGE(Frequency!E2:E56,5),Frequency!E2:E56,0)) -> 46 | K9: =LARGE(Frequency!E2:E56,5) -> 8 | M9: =INDEX(Frequency!$A$2:$A$59,MATCH(LARGE(Frequency!F2:F59,5),Frequency!F2:F59,0)) -> 9 | N9: =LARGE(Frequency!F2:F59,5) -> 8
A11: Cold # | B11: Hits | D11: Cold # | E11: Hits | G11: Cold # | H11: Hits | J11: Cold # | K11: Hits | M11: Cold # | N11: Hits
A12: =INDEX(Frequency!$A$2:$A$43,MATCH(SMALL(Frequency!B2:B43,1),Frequency!B2:B43,0)) -> 14 | B12: =SMALL(Frequency!B2:B43,1) -> 3 | D12: =INDEX(Frequency!$A$2:$A$46,MATCH(SMALL(Frequency!C2:C46,1),Frequency!C2:C46,0)) -> 30 | E12: =SMALL(Frequency!C2:C46,1) -> 1 | G12: =INDEX(Frequency!$A$2:$A$50,MATCH(SMALL(Frequency!D2:D50,1),Frequency!D2:D50,0)) -> 30 | H12: =SMALL(Frequency!D2:D50,1) -> 2 | J12: =INDEX(Frequency!$A$2:$A$56,MATCH(SMALL(Frequency!E2:E56,1),Frequency!E2:E56,0)) -> 14 | K12: =SMALL(Frequency!E2:E56,1) -> 1 | M12: =INDEX(Frequency!$A$2:$A$59,MATCH(SMALL(Frequency!F2:F59,1),Frequency!F2:F59,0)) -> 18 | N12: =SMALL(Frequency!F2:F59,1) -> 1
A13: =INDEX(Frequency!$A$2:$A$43,MATCH(SMALL(Frequency!B2:B43,2),Frequency!B2:B43,0)) -> 14 | B13: =SMALL(Frequency!B2:B43,2) -> 3 | D13: =INDEX(Frequency!$A$2:$A$46,MATCH(SMALL(Frequency!C2:C46,2),Frequency!C2:C46,0)) -> 30 | E13: =SMALL(Frequency!C2:C46,2) -> 1 | G13: =INDEX(Frequency!$A$2:$A$50,MATCH(SMALL(Frequency!D2:D50,2),Frequency!D2:D50,0)) -> 30 | H13: =SMALL(Frequency!D2:D50,2) -> 2 | J13: =INDEX(Frequency!$A$2:$A$56,MATCH(SMALL(Frequency!E2:E56,2),Frequency!E2:E56,0)) -> 14 | K13: =SMALL(Frequency!E2:E56,2) -> 1 | M13: =INDEX(Frequency!$A$2:$A$59,MATCH(SMALL(Frequency!F2:F59,2),Frequency!F2:F59,0)) -> 18 | N13: =SMALL(Frequency!F2:F59,2) -> 1
A14: =INDEX(Frequency!$A$2:$A$43,MATCH(SMALL(Frequency!B2:B43,3),Frequency!B2:B43,0)) -> 14 | B14: =SMALL(Frequency!B2:B43,3) -> 3 | D14: =INDEX(Frequency!$A$2:$A$46,MATCH(SMALL(Frequency!C2:C46,3),Frequency!C2:C46,0)) -> 26 | E14: =SMALL(Frequency!C2:C46,3) -> 2 | G14: =INDEX(Frequency!$A$2:$A$50,MATCH(SMALL(Frequency!D2:D50,3),Frequency!D2:D50,0)) -> 5 | H14: =SMALL(Frequency!D2:D50,3) -> 3 | J14: =INDEX(Frequency!$A$2:$A$56,MATCH(SMALL(Frequency!E2:E56,3),Frequency!E2:E56,0)) -> 6 | K14: =SMALL(Frequency!E2:E56,3) -> 2 | M14: =INDEX(Frequency!$A$2:$A$59,MATCH(SMALL(Frequency!F2:F59,3),Frequency!F2:F59,0)) -> 18 | N14: =SMALL(Frequency!F2:F59,3) -> 1
A15: =INDEX(Frequency!$A$2:$A$43,MATCH(SMALL(Frequency!B2:B43,4),Frequency!B2:B43,0)) -> 14 | B15: =SMALL(Frequency!B2:B43,4) -> 3 | D15: =INDEX(Frequency!$A$2:$A$46,MATCH(SMALL(Frequency!C2:C46,4),Frequency!C2:C46,0)) -> 2 | E15: =SMALL(Frequency!C2:C46,4) -> 3 | G15: =INDEX(Frequency!$A$2:$A$50,MATCH(SMALL(Frequency!D2:D50,4),Frequency!D2:D50,0)) -> 5 | H15: =SMALL(Frequency!D2:D50,4) -> 3 | J15: =INDEX(Frequency!$A$2:$A$56,MATCH(SMALL(Frequency!E2:E56,4),Frequency!E2:E56,0)) -> 6 | K15: =SMALL(Frequency!E2:E56,4) -> 2 | M15: =INDEX(Frequency!$A$2:$A$59,MATCH(SMALL(Frequency!F2:F59,4),Frequency!F2:F59,0)) -> 10 | N15: =SMALL(Frequency!F2:F59,4) -> 2
A16: =INDEX(Frequency!$A$2:$A$43,MATCH(SMALL(Frequency!B2:B43,5),Frequency!B2:B43,0)) -> 4 | B16: =SMALL(Frequency!B2:B43,5) -> 4 | D16: =INDEX(Frequency!$A$2:$A$46,MATCH(SMALL(Frequency!C2:C46,5),Frequency!C2:C46,0)) -> 2 | E16: =SMALL(Frequency!C2:C46,5) -> 3 | G16: =INDEX(Frequency!$A$2:$A$50,MATCH(SMALL(Frequency!D2:D50,5),Frequency!D2:D50,0)) -> 5 | H16: =SMALL(Frequency!D2:D50,5) -> 3 | J16: =INDEX(Frequency!$A$2:$A$56,MATCH(SMALL(Frequency!E2:E56,5),Frequency!E2:E56,0)) -> 6 | K16: =SMALL(Frequency!E2:E56,5) -> 2 | M16: =INDEX(Frequency!$A$2:$A$59,MATCH(SMALL(Frequency!F2:F59,5),Frequency!F2:F59,0)) -> 10 | N16: =SMALL(Frequency!F2:F59,5) -> 2
A18: Note: ties resolved to the lowest number; see Frequency sheet for full counts.

Sheet Moon-Sun Test
A1: Game | B1: Draw Date | C1: Moon Alt (deg) | D1: Moon Az (deg) | E1: Moon Illum (0-1) | F1: Moon Dist (km) | G1: Lunar tidal accel (g) | H1: Sun Alt (deg) | I1: Mean drawn # / pool | J1: Kp at draw (geomagnetic) | K1: Kp daily mean
A2: Lotto 6/42 | B2: 2026-03-10 | C2: -37.24 | D2: 113.3 | E2: 0.583 | F2: 408208 | G2: 4.41e-15 | H2: -42.99 | I2: 0.4087 | J2: 2.667 | K2: 2.667
A3: Lotto 6/42 | B3: 2026-03-12 | C3: -58.54 | D3: 120.2 | E3: 0.394 | F3: 407286 | G3: 4.44e-15 | H3: -42.89 | I3: 0.5635 | J3: 2 | K3: 1.792
A4: Lotto 6/42 | B4: 2026-03-14 | C4: -79.19 | D4: 147.3 | E4: 0.215 | F4: 400968 | G4: 4.65e-15 | H4: -42.78 | I4: 0.5357 | J4: 5 | K4: 4.5
A5: Lotto 6/42 | B5: 2026-03-17 | C5: -62.24 | D5: 278.6 | E5: 0.028 | F5: 385532 | G5: 5.23e-15 | H5: -42.61 | I5: 0.4405 | J5: 0.667 | K5: 0.833
A6: Lotto 6/42 | B6: 2026-03-19 | C6: -37.09 | D6: 286.6 | E6: 0.004 | F6: 375440 | G6: 5.67e-15 | H6: -42.49 | I6: 0.5873 | J6: 1 | K6: 0.333
A7: Lotto 6/42 | B7: 2026-03-21 | C7: -10.58 | D7: 290.3 | E7: 0.082 | F7: 368448 | G7: 6.00e-15 | H7: -42.36 | I7: 0.4881 | J7: 3.333 | K7: 4.292
A8: Lotto 6/42 | B8: 2026-03-24 | C8: 30.01 | D8: 294.2 | E8: 0.358 | F8: 365497 | G8: 6.14e-15 | H8: -42.15 | I8: 0.6349 | J8: 3 | K8: 3
A9: Lotto 6/42 | B9: 2026-03-26 | C9: 56.7 | D9: 297 | E9: 0.585 | F9: 367702 | G9: 6.03e-15 | H9: -42 | I9: 0.4683 | J9: 2.333 | K9: 2.125
A10: Lotto 6/42 | B10: 2026-03-28 | C10: 82.65 | D10: 309.6 | E10: 0.788 | F10: 372301 | G10: 5.81e-15 | H10: -41.84 | I10: 0.2063 | J10: 1.333 | K10: 2.125
A11: Lotto 6/42 | B11: 2026-03-31 | C11: 59.3 | D11: 112.5 | E11: 0.975 | F11: 382803 | G11: 5.35e-15 | H11: -41.58 | I11: 0.4405 | J11: 2 | K11: 1.625
A12: Lotto 6/42 | B12: 2026-04-07 | C12: -20.9 | D12: 114.9 | E12: 0.744 | F12: 407177 | G12: 4.44e-15 | H12: -40.91 | I12: 0.5476 | J12: 1.667 | K12: 1.833
A13: Lotto 6/42 | B13: 2026-04-09 | C13: -42.69 | D13: 113.5 | E13: 0.565 | F13: 406393 | G13: 4.47e-15 | H13: -40.7 | I13: 0.4127 | J13: 2.333 | K13: 1.542
... A39: Lotto 6/42 | B39: 2026-06-09 | C39: -53.6 | D39: 63.6 | E39: 0.383 | F39: 384177 | G39: 5.29e-15 | H39: -33.04 | I39: 0.6587 | J39: 2.667 | K39: 2.542
A40: Lotto 6/42 | B40: 2026-06-11 | C40: -59.01 | D40: 17.2 | E40: 0.182 | F40: 372901 | G40: 5.78e-15 | H40: -32.88 | I40: 0.4603
A41: Lotto 6/42 | B41: 2026-06-13 | C41: -47.08 | D41: 335.1 | E41: 0.04 | F41: 363809 | G41: 6.23e-15 | H41: -32.73 | I41: 0.5556
A42: Lotto 6/42 | B42: 2026-06-16 | C42: -14.5 | D42: 302.1 | E42: 0.032 | F42: 361115 | G42: 6.37e-15 | H42: -32.53 | I42: 0.7817
A43: Mega Lotto 6/45 | B43: 2026-03-11 | C43: -47.9 | D43: 116.2 | E43: 0.488 | F43: 408474 | G43: 4.40e-15 | H43: -42.94 | I43: 0.5148 | J43: 2.333 | K43: 2.083
A44: Mega Lotto 6/45 | B44: 2026-03-13 | C44: -69.15 | D44: 127.4 | E44: 0.302 | F44: 404724 | G44: 4.52e-15 | H44: -42.84 | I44: 0.6333 | J44: 1.667 | K44: 3.25
A45: Mega Lotto 6/45 | B45: 2026-03-16 | C45: -73.86 | D45: 267.6 | E45: 0.074 | F45: 391014 | G45: 5.02e-15 | H45: -42.67 | I45: 0.4852 | J45: 2 | K45: 1.917
A46: Mega Lotto 6/45 | B46: 2026-03-18 | C46: -49.89 | D46: 283.6 | E46: 0.003 | F46: 380224 | G46: 5.46e-15 | H46: -42.55 | I46: 0.5296 | J46: 0.667 | K46: 0.917
A47: Mega Lotto 6/45 | B47: 2026-03-20 | C47: -23.95 | D47: 288.7 | E47: 0.03 | F47: 371456 | G47: 5.85e-15 | H47: -42.42 | I47: 0.4074 | J47: 3 | K47: 3.625
A48: Mega Lotto 6/45 | B48: 2026-03-23 | C48: 16.52 | D48: 293 | E48: 0.252 | F48: 365530 | G48: 6.14e-15 | H48: -42.22 | I48: 0.4963 | J48: 4.667 | K48: 4.125
A49: Mega Lotto 6/45 | B49: 2026-03-25 | C49: 43.42 | D49: 295.4 | E49: 0.472 | F49: 366259 | G49: 6.10e-15 | H49: -42.07 | I49: 0.3704 | J49: 1 | K49: 2.5
A50: Mega Lotto 6/45 | B50: 2026-03-27 | C50: 69.82 | D50: 299.7 | E50: 0.692 | F50: 369735 | G50: 5.93e-15 | H50: -41.92 | I50: 0.5667 | J50: 1 | K50: 1.583
A51: Mega Lotto 6/45 | B51: 2026-03-30 | C51: 71.63 | D51: 109.8 | E51: 0.932 | F51: 378883 | G51: 5.51e-15 | H51: -41.67 | I51: 0.4333 | J51: 3.333 | K51: 2.333
A52: Mega Lotto 6/45 | B52: 2026-04-01 | C52: 47.18 | D52: 113.7 | E52: 0.996 | F52: 387020 | G52: 5.17e-15 | H52: -41.49 | I52: 0.3852 | J52: 3 | K52: 2
A53: Mega Lotto 6/45 | B53: 2026-04-06 | C53: -9.98 | D53: 115.2 | E53: 0.821 | F53: 405657 | G53: 4.49e-15 | H53: -41.02 | I53: 0.5778 | J53: 2 | K53: 2.167
A54: Mega Lotto 6/45 | B54: 2026-04-08 | C54: -31.78 | D54: 114.4 | E54: 0.658 | F54: 407457 | G54: 4.43e-15 | H54: -40.81 | I54: 0.4889 | J54: 2 | K54: 1.667
... A81: Mega Lotto 6/45 | B81: 2026-06-10 | C81: -58.38 | D81: 42.6 | E81: 0.279 | F81: 378499 | G81: 5.53e-15 | H81: -32.96 | I81: 0.7148 | J81: 2.333 | K81: 1.667
A82: Mega Lotto 6/45 | B82: 2026-06-12 | C82: -54.88 | D82: 353.5 | E82: 0.101 | F82: 367847 | G82: 6.02e-15 | H82: -32.8 | I82: 0.4815
A83: Mega Lotto 6/45 | B83: 2026-06-15 | C83: -26.03 | D83: 311 | E83: 0.004 | F83: 360273 | G83: 6.41e-15 | H83: -32.59 | I83: 0.5259
A84: Super Lotto 6/49 | B84: 2026-03-10 | C84: -37.24 | D84: 113.3 | E84: 0.583 | F84: 408208 | G84: 4.41e-15 | H84: -42.99 | I84: 0.6769 | J84: 2.667 | K84: 2.667
A85: Super Lotto 6/49 | B85: 2026-03-12 | C85: -58.54 | D85: 120.2 | E85: 0.394 | F85: 407286 | G85: 4.44e-15 | H85: -42.89 | I85: 0.432 | J85: 2 | K85: 1.792
A86: Super Lotto 6/49 | B86: 2026-03-15 | C86: -82.84 | D86: 224.7 | E86: 0.138 | F86: 396286 | G86: 4.82e-15 | H86: -42.73 | I86: 0.4592 | J86: 2.667 | K86: 3.083
A87: Super Lotto 6/49 | B87: 2026-03-17 | C87: -62.24 | D87: 278.6 | E87: 0.028 | F87: 385532 | G87: 5.23e-15 | H87: -42.61 | I87: 0.5782 | J87: 0.667 | K87: 0.833
A88: Super Lotto 6/49 | B88: 2026-03-19 | C88: -37.09 | D88: 286.6 | E88: 0.004 | F88: 375440 | G88: 5.67e-15 | H88: -42.49 | I88: 0.4524 | J88: 1 | K88: 0.333
A89: Super Lotto 6/49 | B89: 2026-03-22 | C89: 3.15 | D89: 291.7 | E89: 0.158 | F89: 366482 | G89: 6.09e-15 | H89: -42.29 | I89: 0.6156 | J89: 6 | K89: 5.709
A90: Super Lotto 6/49 | B90: 2026-03-24 | C90: 30.01 | D90: 294.2 | E90: 0.358 | F90: 365497 | G90: 6.14e-15 | H90: -42.15 | I90: 0.5748 | J90: 3 | K90: 3
A91: Super Lotto 6/49 | B91: 2026-03-26 | C91: 56.7 | D91: 297 | E91: 0.585 | F91: 367702 | G91: 6.03e-15 | H91: -42 | I91: 0.4388 | J91: 2.333 | K91: 2.125
...

Sheet EV Calculator
A1: Expected-value calculator (Stern-Cover style). Blue cells = inputs you can change. Yellow = estimates, update from official PCSO figures. This computes whether a ticket is worth its price — it does NOT predict numbers.
A3: Game | B3: Lotto 6/42 | C3: Mega Lotto 6/45 | D3: Super Lotto 6/49 | E3: Grand Lotto 6/55 | F3: Ultra Lotto 6/58
A4: Number pool | B4: 42 | C4: 45 | D4: 49 | E4: 55 | F4: 58
A5: Possible combinations | B5: =COMBIN(B4,6) -> 5245786 | C5: =COMBIN(C4,6) -> 8145060 | D5: =COMBIN(D4,6) -> 13983816 | E5: =COMBIN(E4,6) -> 28989675 | F5: =COMBIN(F4,6) -> 40475358
A6: P(jackpot) | B6: =1/B5 -> 1.906292e-07 | C6: =1/C5 -> 1.227738e-07 | D6: =1/D5 -> 7.1511238e-08 | E6: =1/E5 -> 3.449504e-08 | F6: =1/F5 -> 2.470639e-08
A7: P(match 5) | B7: =6*(B4-6)/B5 -> 4.1175908e-05 | C7: =6*(C4-6)/C5 -> 2.872907e-05 | D7: =6*(D4-6)/D5 -> 1.84499e-05 | E7: =6*(E4-6)/E5 -> 1.0141542e-05 | F7: =6*(F4-6)/F5 -> 7.7083938e-06
A8: P(match 4) | B8: =15*COMBIN(B4-6,2)/B5 -> 0.001801446 | C8: =15*COMBIN(C4-6,2)/C5 -> 0.0013646308 | D8: =15*COMBIN(D4-6,2)/D5 -> 0.00096861972 | E8: =15*COMBIN(E4-6,2)/E5 -> 0.00060849251 | F8: =15*COMBIN(F4-6,2)/F5 -> 0.00049141011
A9: P(match 3) | B9: =20*COMBIN(B4-6,3)/B5 -> 0.02722185 | C9: =20*COMBIN(C4-6,3)/C5 -> 0.022440596 | D9: =20*COMBIN(D4-6,3)/D5 -> 0.017650404 | E9: =20*COMBIN(E4-6,3)/E5 -> 0.012710732 | F9: =20*COMBIN(F4-6,3)/F5 -> 0.010920225
A11: INPUT: Current jackpot (PHP) | B11: 20676273 | C11: 52078363 | D11: 25000000 | E11: 45000000 | F11: 75000000
A12: INPUT: Est. tickets sold this draw | B12: 400000 | C12: 500000 | D12: 500000 | E12: 600000 | F12: 700000
A13: INPUT: Match-5 prize (PHP) | B13: 24000 | C13: 32000 | D13: 56000 | E13: 200000 | F13: 280000
A14: INPUT: Match-4 prize (PHP) | B14: 800 | C14: 1000 | D14: 1200 | E14: 3000 | F14: 4000
A15: INPUT: Match-3 prize (PHP) | B15: 20 | C15: 30 | D15: 50 | E15: 60 | F15: 100
A17: Expected co-winners (Poisson lambda) | B17: =B12*B6 -> 0.076251681 | C17: =C12*C6 -> 0.061386902 | D17: =D12*D6 -> 0.035755619 | E17: =E12*E6 -> 0.020697024 | F17: =F12*F6 -> 0.017294473
A18: Expected jackpot share if you win | B18: =B11*(1-EXP(-B17))/B17 -> 19907633 | C18: =C11*(1-EXP(-C17))/C17 -> 50512111 | D18: =D11*(1-EXP(-D17))/D17 -> 24558334 | E18: =E11*(1-EXP(-E17))/E17 -> 44537513 | F18: =F11*(1-EXP(-F17))/F17 -> 74355180
A19: ...after 20% tax | B19: =B18*0.8 -> 15926106 | C19: =C18*0.8 -> 40409689 | D19: =D18*0.8 -> 19646668 | E19: =E18*0.8 -> 35630011 | F19: =F18*0.8 -> 59484144
A20: EV from jackpot (PHP) | B20: =B6*B19 -> 3.0359809 | C20: =C6*C19 -> 4.9612512 | D20: =D6*D19 -> 1.4049575 | E20: =E6*E19 -> 1.2290586 | F20: =F6*F19 -> 1.4696385
A21: EV from lower tiers (PHP) | B21: =B7*B13*0.8+B8*B14*IF(B14>10000,0.8,1)+B9*B15 -> 2.7761712 | C21: =C7*C13*0.8+C8*C14*IF(C14>10000,0.8,1)+C9*C15 -> 2.7733129 | D21: =D7*D13*0.8+D8*D14*IF(D14>10000,0.8,1)+D9*D15 -> 2.8714194 | E21: =E7*E13*0.8+E8*E14*IF(E14>10000,0.8,1)+E9*E15 -> 4.2107681 | F21: =F7*F13*0.8+F8*F14*IF(F14>10000,0.8,1)+F9*F15 -> 4.7843431
A22: Total EV per ticket (PHP) | B22: =B20+B21 -> 5.8121521 | C22: =C20+C21 -> 7.7345641 | D22: =D20+D21 -> 4.2763769 | E22: =E20+E21 -> 5.4398268 | F22: =F20+F21 -> 6.2539816
A23: Net EV per PHP25 ticket | B23: =B22-25 -> -19.187848 | C23: =C22-25 -> -17.265436 | D23: =D22-25 -> -20.723623 | E23: =E22-25 -> -19.560173 | F23: =F22-25 -> -18.746018
A24: Return per peso bet | B24: =B22/25 -> 0.23248609 | C24: =C22/25 -> 0.30938256 | D24: =D22/25 -> 0.17105508 | E24: =E22/25 -> 0.21759307 | F24: =F22/25 -> 0.25015926
A25: Break-even jackpot, no split (PHP) | B25: =(25-B21)/(0.8*B6) -> 1.4572681e+08 | C25: =(25-C21)/(0.8*C6) -> 226297125 | D25: =(25-D21)/(0.8*D6) -> 386802500 | E25: =(25-E21)/(0.8*E6) -> 7.5334134e+08 | F25: =(25-F21)/(0.8*F6) -> 1.0227949e+09
A26: Verdict | B26: =IF(B23>0,"+EV — rare, check split risk","-EV: entertainment only") -> -EV: entertainment only | C26: =IF(C23>0,"+EV — rare, check split risk","-EV: entertainment only") -> -EV: entertainment only | D26: =IF(D23>0,"+EV — rare, check split risk","-EV: entertainment only") -> -EV: entertainment only | E26: =IF(E23>0,"+EV — rare, check split risk","-EV: entertainment only") -> -EV: entertainment only | F26: =IF(F23>0,"+EV — rare, check split risk","-EV: entertainment only") -> -EV: entertainment only
A28: Notes: Jackpot prefilled from the latest draw in this workbook — update before using.
A29: Match-5/4 prizes are pari-mutuel estimates (yellow) — check pcso.gov.ph for current values; match-3 is fixed.
A30: Split adjustment: if you win, expected share = J*(1-EXP(-lambda))/lambda where lambda = tickets*P(jackpot) (Poisson co-winners).
A31: Doob's optional stopping theorem still applies: a positive-EV draw is the ONLY mathematically meaningful green light, and even then variance is brutal.
A32: Tax: 20% withheld on prizes over PHP10,000 (TRAIN law).

Sheet Protocol
A1: THE 2-TICKET PROTOCOL — everything mathematics offers a seldom player
A3: 1. WHEN: play only deep rollovers — check the EV Calculator sheet first. EV varies ~5x with jackpot size. | H3: =RAND() -> 0.11937101 | I3: =RAND() -> 0.28830916 | J3: =RAND() -> 0.055204295 | K3: =RAND() -> 0.79672874 | L3: =RAND() -> 0.25112289
A4: 2. DISJOINT: two tickets, no shared numbers (12 distinct). Exactly doubles jackpot odds to 2/C(n,6) — the only rigorous improvement. | H4: =RAND() -> 0.20039116 | I4: =RAND() -> 0.48354618 | J4: =RAND() -> 0.616812 | K4: =RAND() -> 0.49168133 | L4: =RAND() -> 0.46458233
A5: 3. UNPOPULAR: reject pattern-like picks (all numbers <=31, sequences, multiples). Changes expected payout via split avoidance, not odds. | H5: =RAND() -> 0.21129215 | I5: =RAND() -> 0.62996045 | J5: =RAND() -> 0.78640696 | K5: =RAND() -> 0.69961265 | L5: =RAND() -> 0.72995786
A6: 4. LOG: record every play. Expected cost ~PHP17-20 per PHP25 ticket — price it as entertainment. | H6: =RAND() -> 0.91860671 | I6: =RAND() -> 0.7381482 | J6: =RAND() -> 0.084550452 | K6: =RAND() -> 0.029040915 | L6: =RAND() -> 0.52030478
A7: Generator below: press F9 to regenerate. Tickets A and B are guaranteed disjoint (rank-split of one random shuffle). | H7: =RAND() -> 0.44583556 | I7: =RAND() -> 0.90414487 | J7: =RAND() -> 0.28402558 | K7: =RAND() -> 0.75230891 | L7: =RAND() -> 0.37498418
H8: =RAND() -> 0.64001465 | I8: =RAND() -> 0.80568412 | J8: =RAND() -> 0.41330641 | K8: =RAND() -> 0.013317233 | L8: =RAND() -> 0.38271905
H9: =RAND() -> 0.53108518 | I9: =RAND() -> 0.53791478 | J9: =RAND() -> 0.3330197 | K9: =RAND() -> 0.313279 | L9: =RAND() -> 0.67033262
B10: Lotto 6/42 | C10: Mega Lotto 6/45 | D10: Super Lotto 6/49 | E10: Grand Lotto 6/55 | F10: Ultra Lotto 6/58 | H10: =RAND() -> 0.24468051 | I10: =RAND() -> 0.012312478 | J10: =RAND() -> 0.40203182 | K10: =RAND() -> 0.20220039 | L10: =RAND() -> 0.79561785
A11: Pattern check | B11: Ticket A | C11: Ticket A | D11: Ticket A | E11: Ticket A | F11: Ticket A | H11: =RAND() -> 0.48857288 | I11: =RAND() -> 0.042247925 | J11: =RAND() -> 0.2066023 | K11: =RAND() -> 0.20198143 | L11: =RAND() -> 0.60360867
B12: =MATCH(LARGE(H$3:H$44,1),H$3:H$44,0) -> 39 | C12: =MATCH(LARGE(I$3:I$47,1),I$3:I$47,0) -> 12 | D12: =MATCH(LARGE(J$3:J$51,1),J$3:J$51,0) -> 12 | E12: =MATCH(LARGE(K$3:K$57,1),K$3:K$57,0) -> 41 | F12: =MATCH(LARGE(L$3:L$60,1),L$3:L$60,0) -> 19 | H12: =RAND() -> 0.27420729 | I12: =RAND() -> 0.066368797 | J12: =RAND() -> 0.86671878 | K12: =RAND() -> 0.49244319 | L12: =RAND() -> 0.68552429
B13: =MATCH(LARGE(H$3:H$44,2),H$3:H$44,0) -> 29 | C13: =MATCH(LARGE(I$3:I$47,2),I$3:I$47,0) -> 42 | D13: =MATCH(LARGE(J$3:J$51,2),J$3:J$51,0) -> 18 | E13: =MATCH(LARGE(K$3:K$57,2),K$3:K$57,0) -> 48 | F13: =MATCH(LARGE(L$3:L$60,2),L$3:L$60,0) -> 14 | H13: =RAND() -> 0.4702198 | I13: =RAND() -> 0.14253926 | J13: =RAND() -> 0.31709006 | K13: =RAND() -> 0.64880808 | L13: =RAND() -> 0.34128898
B14: =MATCH(LARGE(H$3:H$44,3),H$3:H$44,0) -> 30 | C14: =MATCH(LARGE(I$3:I$47,3),I$3:I$47,0) -> 16 | D14: =MATCH(LARGE(J$3:J$51,3),J$3:J$51,0) -> 34 | E14: =MATCH(LARGE(K$3:K$57,3),K$3:K$57,0) -> 51 | F14: =MATCH(LARGE(L$3:L$60,3),L$3:L$60,0) -> 39 | H14: =RAND() -> 0.67449346 | I14: =RAND() -> 0.97365944 | J14: =RAND() -> 0.987301 | K14: =RAND() -> 0.41516957 | L14: =RAND() -> 0.40948523
B15: =MATCH(LARGE(H$3:H$44,4),H$3:H$44,0) -> 4 | C15: =MATCH(LARGE(I$3:I$47,4),I$3:I$47,0) -> 45 | D15: =MATCH(LARGE(J$3:J$51,4),J$3:J$51,0) -> 15 | E15: =MATCH(LARGE(K$3:K$57,4),K$3:K$57,0) -> 33 | F15: =MATCH(LARGE(L$3:L$60,4),L$3:L$60,0) -> 47 | H15: =RAND() -> 0.62223754 | I15: =RAND() -> 0.28711891 | J15: =RAND() -> 0.76851002 | K15: =RAND() -> 0.14902784 | L15: =RAND() -> 0.12895766
B16: =MATCH(LARGE(H$3:H$44,5),H$3:H$44,0) -> 21 | C16: =MATCH(LARGE(I$3:I$47,5),I$3:I$47,0) -> 37 | D16: =MATCH(LARGE(J$3:J$51,5),J$3:J$51,0) -> 10 | E16: =MATCH(LARGE(K$3:K$57,5),K$3:K$57,0) -> 24 | F16: =MATCH(LARGE(L$3:L$60,5),L$3:L$60,0) -> 8 | H16: =RAND() -> 0.69159513 | I16: =RAND() -> 0.15082794 | J16: =RAND() -> 0.17162111 | K16: =RAND() -> 0.033826105 | L16: =RAND() -> 0.84865704
B17: =MATCH(LARGE(H$3:H$44,6),H$3:H$44,0) -> 27 | C17: =MATCH(LARGE(I$3:I$47,6),I$3:I$47,0) -> 5 | D17: =MATCH(LARGE(J$3:J$51,6),J$3:J$51,0) -> 35 | E17: =MATCH(LARGE(K$3:K$57,6),K$3:K$57,0) -> 16 | F17: =MATCH(LARGE(L$3:L$60,6),L$3:L$60,0) -> 30 | H17: =RAND() -> 0.47686761 | I17: =RAND() -> 0.68787049 | J17: =RAND() -> 0.87200964 | K17: =RAND() -> 0.4640292 | L17: =RAND() -> 0.59403451
B18: Ticket B | C18: Ticket B | D18: Ticket B | E18: Ticket B | F18: Ticket B | H18: =RAND() -> 0.51339709 | I18: =RAND() -> 0.9286514 | J18: =RAND() -> 0.585099 | K18: =RAND() -> 0.9294942 | L18: =RAND() -> 0.18734135
B19: =MATCH(LARGE(H$3:H$44,7),H$3:H$44,0) -> 23 | C19: =MATCH(LARGE(I$3:I$47,7),I$3:I$47,0) -> 25 | D19: =MATCH(LARGE(J$3:J$51,7),J$3:J$51,0) -> 26 | E19: =MATCH(LARGE(K$3:K$57,7),K$3:K$57,0) -> 39 | F19: =MATCH(LARGE(L$3:L$60,7),L$3:L$60,0) -> 45 | H19: =RAND() -> 0.0040734085 | I19: =RAND() -> 0.36912942 | J19: =RAND() -> 0.34833324 | K19: =RAND() -> 0.7197055 | L19: =RAND() -> 0.16692823
B20: =MATCH(LARGE(H$3:H$44,8),H$3:H$44,0) -> 20 | C20: =MATCH(LARGE(I$3:I$47,8),I$3:I$47,0) -> 6 | D20: =MATCH(LARGE(J$3:J$51,8),J$3:J$51,0) -> 21 | E20: =MATCH(LARGE(K$3:K$57,8),K$3:K$57,0) -> 44 | F20: =MATCH(LARGE(L$3:L$60,8),L$3:L$60,0) -> 3 | H20: =RAND() -> 0.66330487 | I20: =RAND() -> 0.46351772 | J20: =RAND() -> 0.97121655 | K20: =RAND() -> 0.66570202 | L20: =RAND() -> 0.21980556
B21: =MATCH(LARGE(H$3:H$44,9),H$3:H$44,0) -> 42 | C21: =MATCH(LARGE(I$3:I$47,9),I$3:I$47,0) -> 39 | D21: =MATCH(LARGE(J$3:J$51,9),J$3:J$51,0) -> 3 | E21: =MATCH(LARGE(K$3:K$57,9),K$3:K$57,0) -> 38 | F21: =MATCH(LARGE(L$3:L$60,9),L$3:L$60,0) -> 31 | H21: =RAND() -> 0.41147171 | I21: =RAND() -> 0.11933891 | J21: =RAND() -> 0.10661541 | K21: =RAND() -> 0.32720219 | L21: =RAND() -> 0.98602589
B22: =MATCH(LARGE(H$3:H$44,10),H$3:H$44,0) -> 14 | C22: =MATCH(LARGE(I$3:I$47,10),I$3:I$47,0) -> 40 | D22: =MATCH(LARGE(J$3:J$51,10),J$3:J$51,0) -> 13 | E22: =MATCH(LARGE(K$3:K$57,10),K$3:K$57,0) -> 46 | F22: =MATCH(LARGE(L$3:L$60,10),L$3:L$60,0) -> 10 | H22: =RAND() -> 0.85339253 | I22: =RAND() -> 0.44076411 | J22: =RAND() -> 0.24461387 | K22: =RAND() -> 0.03318244 | L22: =RAND() -> 0.36085443
B23: =MATCH(LARGE(H$3:H$44,11),H$3:H$44,0) -> 12 | C23: =MATCH(LARGE(I$3:I$47,11),I$3:I$47,0) -> 43 | D23: =MATCH(LARGE(J$3:J$51,11),J$3:J$51,0) -> 37 | E23: =MATCH(LARGE(K$3:K$57,11),K$3:K$57,0) -> 28 | F23: =MATCH(LARGE(L$3:L$60,11),L$3:L$60,0) -> 7 | H23: =RAND() -> 0.88710892 | I23: =RAND() -> 0.22322359 | J23: =RAND() -> 0.80994471 | K23: =RAND() -> 0.18534847 | L23: =RAND() -> 0.37013391
B24: =MATCH(LARGE(H$3:H$44,12),H$3:H$44,0) -> 18 | C24: =MATCH(LARGE(I$3:I$47,12),I$3:I$47,0) -> 41 | D24: =MATCH(LARGE(J$3:J$51,12),J$3:J$51,0) -> 33 | E24: =MATCH(LARGE(K$3:K$57,12),K$3:K$57,0) -> 25 | F24: =MATCH(LARGE(L$3:L$60,12),L$3:L$60,0) -> 54 | H24: =RAND() -> 0.59933061 | I24: =RAND() -> 0.61537758 | J24: =RAND() -> 0.12558463 | K24: =RAND() -> 0.42936816 | L24: =RAND() -> 0.30269397
B25: =IF(MAX(B12:B17)<=31,"A: birthday-heavy — F9","A: OK") -> A: OK | C25: =IF(MAX(C12:C17)<=31,"A: birthday-heavy — F9","A: OK") -> A: OK | D25: =IF(MAX(D12:D17)<=31,"A: birthday-heavy — F9","A: OK") -> A: OK | E25: =IF(MAX(E12:E17)<=31,"A: birthday-heavy — F9","A: OK") -> A: OK | F25: =IF(MAX(F12:F17)<=31,"A: birthday-heavy — F9","A: OK") -> A: OK | H25: =RAND() -> 0.85987779 | I25: =RAND() -> 0.15319835 | J25: =RAND() -> 0.23108104 | K25: =RAND() -> 0.096121151 | L25: =RAND() -> 0.60143833
B26: =IF(MAX(B19:B24)<=31,"B: birthday-heavy — F9","B: OK") -> B: OK | C26: =IF(MAX(C19:C24)<=31,"B: birthday-heavy — F9","B: OK") -> B: OK | D26: =IF(MAX(D19:D24)<=31,"B: birthday-heavy — F9","B: OK") -> B: OK | E26: =IF(MAX(E19:E24)<=31,"B: birthday-heavy — F9","B: OK") -> B: OK | F26: =IF(MAX(F19:F24)<=31,"B: birthday-heavy — F9","B: OK") -> B: OK | H26: =RAND() -> 0.40330123 | I26: =RAND() -> 0.50026641 | J26: =RAND() -> 0.11524295 | K26: =RAND() -> 0.93343878 | L26: =RAND() -> 0.48534819
H27: =RAND() -> 0.64060521 | I27: =RAND() -> 0.86196605 | J27: =RAND() -> 0.32595138 | K27: =RAND() -> 0.79884681 | L27: =RAND() -> 0.58752596
H28: =RAND() -> 0.35106257 | I28: =RAND() -> 0.66275143 | J28: =RAND() -> 0.81023599 | K28: =RAND() -> 0.17993727 | L28: =RAND() -> 0.2572558
H29: =RAND() -> 0.87819434 | I29: =RAND() -> 0.098818098 | J29: =RAND() -> 0.1817039 | K29: =RAND() -> 0.03745342 | L29: =RAND() -> 0.49490827
H30: =RAND() -> 0.3444021 | I30: =RAND() -> 0.42900597 | J30: =RAND() -> 0.43125705 | K30: =RAND() -> 0.80095568 | L30: =RAND() -> 0.38392031
H31: =RAND() -> 0.93834788 | I31: =RAND() -> 0.063281057 | J31: =RAND() -> 0.4005706 | K31: =RAND() -> 0.057360757 | L31: =RAND() -> 0.010408021
H32: =RAND() -> 0.92675814 | I32: =RAND() -> 0.4357112 | J32: =RAND() -> 0.2036598 | K32: =RAND() -> 0.45897262 | L32: =RAND() -> 0.77894477
H33: =RAND() -> 0.29444898 | I33: =RAND() -> 0.078327516 | J33: =RAND() -> 0.51939278 | K33: =RAND() -> 0.53598017 | L33: =RAND() -> 0.72790974
H34: =RAND() -> 0.111754 | I34: =RAND() -> 0.16727556 | J34: =RAND() -> 0.38992112 | K34: =RAND() -> 0.46551018 | L34: =RAND() -> 0.26672899
H35: =RAND() -> 0.17449187 | I35: =RAND() -> 0.26171335 | J35: =RAND() -> 0.73802018 | K35: =RAND() -> 0.94543412 | L35: =RAND() -> 0.13236872
H36: =RAND() -> 0.56712612 | I36: =RAND() -> 0.69012496 | J36: =RAND() -> 0.95033847 | K36: =RAND() -> 0.72693071 | L36: =RAND() -> 0.35880444
H37: =RAND() -> 0.086245376 | I37: =RAND() -> 0.73367369 | J37: =RAND() -> 0.82011361 | K37: =RAND() -> 0.76129216 | L37: =RAND() -> 0.19037132
H38: =RAND() -> 0.36223732 | I38: =RAND() -> 0.61886858 | J38: =RAND() -> 0.67051774 | K38: =RAND() -> 0.26858827 | L38: =RAND() -> 0.073799501
... H44: =RAND() -> 0.78020084 | I44: =RAND() -> 0.94151949 | J44: =RAND() -> 0.20857071 | K44: =RAND() -> 0.011064363 | L44: =RAND() -> 0.45390454
I45: =RAND() -> 0.76353317 | J45: =RAND() -> 0.70726817 | K45: =RAND() -> 0.73615918 | L45: =RAND() -> 0.27978309
I46: =RAND() -> 0.042423055 | J46: =RAND() -> 0.49067422 | K46: =RAND() -> 0.9125293 | L46: =RAND() -> 0.62666466
...

Sheet Future Draws
A1: Updated Jun 11, 2026 after 30+ hypothesis tests (all null) and full data validation. Tickets A & B are RANDOM, DISJOINT (doubles jackpot odds vs one ticket) and pattern-filtered (split-risk). They are NOT predictions — 776 draws prove no prediction is possible. Kelly note: even a +EV draw justifies <=PHP25 only on a ~PHP1B bankroll.
A3: Draw Date | B3: Day | C3: Game | D3: Ticket A (random/disjoint) | E3: Ticket B (random/disjoint) | F3: Moon Alt | G3: Moon Illum | H3: Sun Alt
A4: 2026-06-12 | B4: Fri | C4: Mega Lotto 6/45 | D4: 17-18-22-30-37-42 | E4: 10-15-23-25-40-41 | F4: -54.9 | G4: 0.1 | H4: -32.8
A5: 2026-06-12 | B5: Fri | C5: Ultra Lotto 6/58 | D5: 06-07-10-13-30-58 | E5: 04-21-32-34-38-40 | F5: -54.9 | G5: 0.1 | H5: -32.8
A6: 2026-06-13 | B6: Sat | C6: Lotto 6/42 | D6: 01-05-16-33-34-42 | E6: 12-20-22-26-30-40 | F6: -47.1 | G6: 0.04 | H6: -32.7
A7: 2026-06-13 | B7: Sat | C7: Grand Lotto 6/55 | D7: 18-24-35-41-46-50 | E7: 01-09-10-37-49-54 | F7: -47.1 | G7: 0.04 | H7: -32.7
A8: 2026-06-14 | B8: Sun | C8: Super Lotto 6/49 | D8: 04-13-34-37-41-42 | E8: 09-14-25-32-47-49 | F8: -37.1 | G8: 0.01 | H8: -32.7
A9: 2026-06-14 | B9: Sun | C9: Ultra Lotto 6/58 | D9: 08-16-29-46-47-52 | E9: 07-21-25-28-38-42 | F9: -37.1 | G9: 0.01 | H9: -32.7
A10: 2026-06-15 | B10: Mon | C10: Mega Lotto 6/45 | D10: 05-07-15-18-32-34 | E10: 06-19-25-28-36-41 | F10: -26 | G10: 0 | H10: -32.6
A11: 2026-06-15 | B11: Mon | C11: Grand Lotto 6/55 | D11: 03-08-27-40-44-47 | E11: 13-16-28-39-46-50 | F11: -26 | G11: 0 | H11: -32.6
A12: 2026-06-16 | B12: Tue | C12: Lotto 6/42 | D12: 08-14-18-22-26-33 | E12: 01-03-06-16-25-41 | F12: -14.5 | G12: 0.03 | H12: -32.5
A13: 2026-06-16 | B13: Tue | C13: Super Lotto 6/49 | D13: 15-28-32-36-37-39 | E13: 01-16-23-24-30-48 | F13: -14.5 | G13: 0.03 | H13: -32.5
A14: 2026-06-16 | B14: Tue | C14: Ultra Lotto 6/58 | D14: 14-22-33-39-41-43 | E14: 21-24-36-37-42-44 | F14: -14.5 | G14: 0.03 | H14: -32.5
A15: 2026-06-17 | B15: Wed | C15: Mega Lotto 6/45 | D15: 04-05-15-19-37-43 | E15: 06-23-24-26-29-44 | F15: -1.8 | G15: 0.09 | H15: -32.5
... A69: 2026-07-12 | B69: Sun | C69: Ultra Lotto 6/58 | D69: 05-10-28-30-51-52 | E69: 01-15-23-35-39-55 | F69: -45.2 | G69: 0.05 | H69: -32.5
